<?xml version="1.0" encoding="utf-8"?>
<!-- =================================================================================== -->
<!-- |    This document was autogenerated by xacro from be.urdf.xacro                  | -->
<!-- |    EDITING THIS FILE BY HAND IS NOT RECOMMENDED                                 | -->
<!-- =================================================================================== -->
<robot name="be" xmlns:body="http://playerstage.sourceforge.net/gazebo/xmlschema/#body" xmlns:controller="http://playerstage.sourceforge.net/gazebo/xmlschema/#controller" xmlns:gazebo="http://playerstage.sourceforge.net/gazebo/xmlschema/#gz" xmlns:geom="http://playerstage.sourceforge.net/gazebo/xmlschema/#geom" xmlns:interface="http://playerstage.sourceforge.net/gazebo/xmlschema/#interface" xmlns:joint="http://playerstage.sourceforge.net/gazebo/xmlschema/#joint" xmlns:model="http://playerstage.sourceforge.net/gazebo/xmlschema/#model" xmlns:physics="http://playerstage.sourceforge.net/gazebo/xmlschema/#physics" xmlns:renderable="http://playerstage.sourceforge.net/gazebo/xmlschema/#renderable" xmlns:rendering="http://playerstage.sourceforge.net/gazebo/xmlschema/#rendering" xmlns:sensor="http://playerstage.sourceforge.net/gazebo/xmlschema/#sensor" xmlns:xi="http://www.w3.org/2001/XInclude">
  <material name="black">
    <color rgba="0.0 0.0 0.0 1.0"/>
  </material>
  <material name="blue">
    <color rgba="0.0 0.0 0.8 1.0"/>
  </material>
  <material name="green">
    <color rgba="0.0 0.8 0.0 1.0"/>
  </material>
  <material name="grey">
    <color rgba="0.2 0.2 0.2 1.0"/>
  </material>
  <material name="orange">
    <color rgba="1.0 0.423529411765 0.0392156862745 1.0"/>
  </material>
  <material name="brown">
    <color rgba="0.870588235294 0.811764705882 0.764705882353 1.0"/>
  </material>
  <material name="red">
    <color rgba="0.8 0.0 0.0 1.0"/>
  </material>
  <material name="white">
    <color rgba="1.0 1.0 1.0 1.0"/>
  </material>
  <!-- see https://secure.wikimedia.org/wikipedia/en/wiki/List_of_moment_of_inertia_tensors -->
  <!-- p3dx_base_link -->
  <link name="p3dx_base_link"/>
  <!-- Chassis -->
  <joint name="p3dx_base_link_chassis_joint" type="fixed">
    <origin rpy="0 0 0" xyz="0 0 0"/>
    <parent link="p3dx_base_link"/>
    <child link="chassis"/>
  </joint>
  <link name="chassis">
    <visual name="chassis_visual">
      <origin rpy="0 0 0" xyz="-0.045 0 0.148"/>
      <geometry name="pioneer_geom">
        <mesh filename="package://p3dx_robot/meshes/p3dx/chassis.stl"/>
      </geometry>
      <material name="ChassisRed">
        <color rgba="0.851 0.0 0.0 1.0"/>
      </material>
    </visual>
    <collision>
      <origin rpy="0 0 0" xyz="-0.045 0 0.148"/>
      <geometry>
        <mesh filename="package://p3dx_robot/meshes/p3dx/chassis.stl"/>
      </geometry>
    </collision>
    <inertial>
      <mass value="9.0"/>
      <origin xyz="0 0 0"/>
      <inertia ixx="0.07499997" ixy="0.0" ixz="0.0" iyy="0.1214999514" iyz="0.0" izz="0.14789994084"/>
    </inertial>
  </link>
  <gazebo reference="chassis">
    <material value="Gazebo/Red"/>
  </gazebo>
  <!-- Top -->
  <joint name="chassis_top_joint" type="fixed">
    <origin rpy="0 0 0" xyz="-0.045 0 0.234"/>
    <parent link="chassis"/>
    <child link="top"/>
  </joint>
  <link name="top">
    <visual>
      <origin rpy="0 0 0" xyz="0 0 0"/>
      <geometry name="top_geom">
        <mesh filename="package://p3dx_robot/meshes/p3dx/top.stl"/>
      </geometry>
      <material name="TopBlack">
        <color rgba="0.038 0.038 0.038 1.0"/>
      </material>
    </visual>
    <collision>
      <origin rpy="0 0 0" xyz="0.0 0 0.0"/>
      <geometry>
        <mesh filename="package://p3dx_robot/meshes/p3dx/top.stl"/>
      </geometry>
    </collision>
    <inertial>
      <mass value="1.0"/>
      <origin xyz="0 0 0"/>
      <inertia ixx="0.01204166185" ixy="0.0" ixz="0.0" iyy="0.0165104100625" iyz="0.0" izz="0.0285354052525"/>
    </inertial>
  </link>
  <gazebo reference="top">
    <material value="Gazebo/Black"/>
  </gazebo>
  <!-- Front Sonar -->
  <joint name="chassis_sonar_joint" type="fixed">
    <origin rpy="0 0 0" xyz="0.109 0 0.209"/>
    <parent link="chassis"/>
    <child link="sonar"/>
  </joint>
  <link name="sonar">
    <inertial>
      <mass value="0.0001"/>
      <origin xyz="0 0 0"/>
      <inertia ixx="1" ixy="0" ixz="0" iyy="1" iyz="0" izz="1"/>
    </inertial>
    <visual name="front_sonar_vis">
      <origin rpy="0 0 0" xyz="0 0 0"/>
      <geometry name="pioneer_geom">
        <mesh filename="package://p3dx_robot/meshes/p3dx/back_sonar.stl"/>
      </geometry>
      <material name="SonarYellow">
        <color rgba="0.715 0.583 0.210 1.0"/>
      </material>
    </visual>
    <collision>
      <origin rpy="0 0 0" xyz="0 0 0"/>
      <geometry>
        <box size="0.1 0.1 0.1"/>
      </geometry>
    </collision>
  </link>
  <gazebo reference="sonar">
    <material value="Gazebo/Yellow"/>
  </gazebo>
  <joint name="chassis_battery0_joint" type="fixed">
    <origin rpy="0 0 0" xyz="-0.14 0.0 0.13"/>
    <parent link="chassis"/>
    <child link="battery0"/>
  </joint>
  <link name="battery0">
    <visual name="battery0_visual">
      <origin rpy="0 0 0" xyz="0 0 0"/>
      <geometry name="battery0_geometry">
        <box size="0.151 0.065 0.094"/>
      </geometry>
      <material name="battery0_material">
        <color rgba="0.038 0.038 0.038 1.0"/>
      </material>
    </visual>
    <inertial>
      <mass value="2.5"/>
      <origin xyz="0 0 0"/>
      <inertia ixx="0.003520831925" ixy="0.0" ixz="0.0" iyy="0.007604163625" iyz="0.0" izz="0.0040833317"/>
    </inertial>
  </link>
  <gazebo reference="battery0">
    <material value="Gazebo/Black"/>
  </gazebo>
  <!-- Hubcap -->
  <joint name="right_hub_joint" type="continuous">
    <origin rpy="0 0 0" xyz="0  0.15 0.09"/>
    <parent link="chassis"/>
    <child link="right_hub"/>
    <axis xyz="0 1 0"/>
  </joint>
  <link name="right_hub">
    <inertial>
      <mass value="0.01"/>
      <origin xyz="0 0 0"/>
      <inertia ixx="0.012411765597" ixy="0" ixz="0" iyy="0.015218160428" iyz="0" izz="0.011763977943"/>
    </inertial>
    <visual name="base_visual">
      <origin rpy="0 0 0" xyz="0 0 0"/>
      <geometry name="pioneer_geom">
        <mesh filename="package://p3dx_robot/meshes/p3dx/right_hubcap.stl"/>
      </geometry>
      <material name="HubcapYellow">
        <color rgba="1.0 0.811 0.151 1.0"/>
      </material>
    </visual>
    <collision>
      <origin rpy="0 0 0" xyz="0 0 0"/>
      <geometry>
        <box size="0.1 0.1 0.1"/>
      </geometry>
    </collision>
  </link>
  <gazebo reference="right_hub">
    <material value="Gazebo/Yellow"/>
  </gazebo>
  <!-- Wheel -->
  <joint name="right_wheel_joint" type="fixed">
    <axis xyz="0 1 0"/>
    <origin rpy="0 0 0" xyz="0 0 0"/>
    <parent link="right_hub"/>
    <child link="right_wheel"/>
  </joint>
  <link name="right_wheel">
    <inertial>
      <mass value="0.5"/>
      <origin xyz="0 0 0"/>
      <inertia ixx="0.012411765597" ixy="0" ixz="0" iyy="0.015218160428" iyz="0" izz="0.011763977943"/>
    </inertial>
    <visual name="base_visual">
      <origin rpy="0 0 0" xyz="0 0 0"/>
      <geometry name="pioneer_geom">
        <mesh filename="package://p3dx_robot/meshes/p3dx/right_wheel.stl"/>
      </geometry>
      <material name="WheelBlack">
        <color rgba="0.117 0.117 0.117 1"/>
      </material>
    </visual>
    <collision>
      <origin rpy="-1.57079635 0 0" xyz="0 0 0"/>
      <geometry>
        <!--<mesh filename="${meshes}/${side}_wheel.stl"/>-->
        <cylinder length="0.01" radius="0.09"/>
      </geometry>
    </collision>
  </link>
  <gazebo reference="right_wheel">
    <material value="Gazebo/Black"/>
  </gazebo>
  <!-- Hubcap -->
  <joint name="left_hub_joint" type="continuous">
    <origin rpy="0 0 0" xyz="0 -0.15 0.09"/>
    <parent link="chassis"/>
    <child link="left_hub"/>
    <axis xyz="0 1 0"/>
  </joint>
  <link name="left_hub">
    <inertial>
      <mass value="0.01"/>
      <origin xyz="0 0 0"/>
      <inertia ixx="0.012411765597" ixy="0" ixz="0" iyy="0.015218160428" iyz="0" izz="0.011763977943"/>
    </inertial>
    <visual name="base_visual">
      <origin rpy="0 0 0" xyz="0 0 0"/>
      <geometry name="pioneer_geom">
        <mesh filename="package://p3dx_robot/meshes/p3dx/left_hubcap.stl"/>
      </geometry>
      <material name="HubcapYellow">
        <color rgba="1.0 0.811 0.151 1.0"/>
      </material>
    </visual>
    <collision>
      <origin rpy="0 0 0" xyz="0 0 0"/>
      <geometry>
        <box size="0.1 0.1 0.1"/>
      </geometry>
    </collision>
  </link>
  <gazebo reference="left_hub">
    <material value="Gazebo/Yellow"/>
  </gazebo>
  <!-- Wheel -->
  <joint name="left_wheel_joint" type="fixed">
    <axis xyz="0 1 0"/>
    <origin rpy="0 0 0" xyz="0 0 0"/>
    <parent link="left_hub"/>
    <child link="left_wheel"/>
  </joint>
  <link name="left_wheel">
    <inertial>
      <mass value="0.5"/>
      <origin xyz="0 0 0"/>
      <inertia ixx="0.012411765597" ixy="0" ixz="0" iyy="0.015218160428" iyz="0" izz="0.011763977943"/>
    </inertial>
    <visual name="base_visual">
      <origin rpy="0 0 0" xyz="0 0 0"/>
      <geometry name="pioneer_geom">
        <mesh filename="package://p3dx_robot/meshes/p3dx/left_wheel.stl"/>
      </geometry>
      <material name="WheelBlack">
        <color rgba="0.117 0.117 0.117 1"/>
      </material>
    </visual>
    <collision>
      <origin rpy="-1.57079635 0 0" xyz="0 0 0"/>
      <geometry>
        <!--<mesh filename="${meshes}/${side}_wheel.stl"/>-->
        <cylinder length="0.01" radius="0.09"/>
      </geometry>
    </collision>
  </link>
  <gazebo reference="left_wheel">
    <material value="Gazebo/Black"/>
  </gazebo>
  <!-- Swivel -->
  <joint name="chassis_swivel_joint" type="continuous">
    <origin rpy="0 0 0" xyz="-0.185 0 0.055"/>
    <axis xyz="0 0 1"/>
    <anchor xyz="0 0 0"/>
    <limit effort="100" k_velocity="0" velocity="100"/>
    <joint_properties damping="0.0" friction="0.0"/>
    <parent link="chassis"/>
    <child link="swivel"/>
  </joint>
  <link name="swivel">
    <inertial>
      <mass value="0.1"/>
      <origin xyz="0 0 0"/>
      <inertia ixx="0.01" ixy="0" ixz="0" iyy="0.01" iyz="0" izz="0.01"/>
    </inertial>
    <visual name="base_visual">
      <origin rpy="0 0 0" xyz="0 0 0"/>
      <geometry name="pioneer_geom">
        <mesh filename="package://p3dx_robot/meshes/p3dx/swivel.stl"/>
      </geometry>
      <material name="swivel">
        <color rgba="0.5 0.5 0.5 1"/>
      </material>
    </visual>
    <!--collision>
      <origin xyz="0 0 0" rpy="0 0 0"/>
      <geometry>
        <box size="0.1 0.1 0.1"/>
      </geometry>
    </collision-->
  </link>
  <gazebo reference="swivel">
    <material value="Gazebo/Grey"/>
  </gazebo>
  <!-- Center Wheel -->
  <joint name="swivel_wheel_joint" type="continuous">
    <origin rpy="0 0 0" xyz="-0.026 0 -0.016"/>
    <axis xyz="0 1 0"/>
    <anchor xyz="0 0 0"/>
    <limit effort="100" k_velocity="0" velocity="100"/>
    <joint_properties damping="0.0" friction="0.0"/>
    <parent link="swivel"/>
    <child link="center_wheel"/>
  </joint>
  <link name="center_wheel">
    <inertial>
      <mass value="0.1"/>
      <origin xyz="0 0 0"/>
      <inertia ixx="0.012411765597" ixy="-0.000711733678" ixz="0.00050272983" iyy="0.015218160428" iyz="-0.000004273467" izz="0.011763977943"/>
    </inertial>
    <visual name="base_visual">
      <origin rpy="0 0 0" xyz="0 0 0"/>
      <geometry name="pioneer_geom">
        <mesh filename="package://p3dx_robot/meshes/p3dx/center_wheel.stl"/>
      </geometry>
      <material name="WheelBlack">
        <color rgba="0.117 0.117 0.117 1"/>
      </material>
    </visual>
    <collision>
      <origin rpy="0 0 0" xyz="0 0 0"/>
      <geometry>
        <sphere radius=".038"/>
      </geometry>
      <surface>
        <friction>
          <ode mu="0" mu2="0" slip1="1" slip2="1"/>
        </friction>
      </surface>
    </collision>
    <!--collision>
      <origin xyz="0 0 0" rpy="${-3.1415927/2.0} 0 0"/>
      <geometry>
        <!-<mesh filename="${meshes}/center_wheel.stl"/>->
        <cylinder radius="0.0375" length="0.01"/>
      </geometry>
    </collision-->
  </link>
  <gazebo reference="center_wheel">
    <material value="Gazebo/Black"/>
  </gazebo>
  <!-- Center Hubcap -->
  <joint name="wheel_hubcap_joint" type="fixed">
    <origin rpy="0 0 0" xyz="-0.0035 0 -0.001"/>
    <parent link="center_wheel"/>
    <child link="center_hubcap"/>
  </joint>
  <link name="center_hubcap">
    <inertial>
      <mass value="0.01"/>
      <origin xyz="0 0 0"/>
      <inertia ixx="0.012411765597" ixy="-0.000711733678" ixz="0.00050272983" iyy="0.015218160428" iyz="-0.000004273467" izz="0.011763977943"/>
    </inertial>
    <visual name="base_visual">
      <origin rpy="0 0 0" xyz="0 0 0"/>
      <geometry name="pioneer_geom">
        <mesh filename="package://p3dx_robot/meshes/p3dx/center_hubcap.stl"/>
      </geometry>
      <material name="swivel">
        <color rgba="0.5 0.5 0.5 1"/>
      </material>
    </visual>
    <!--collision>
      <origin xyz="0 0 0" rpy="0 0 0"/>
      <geometry>
        <box size="0.07 0.07 0.07"/>
      </geometry>
    </collision-->
  </link>
  <gazebo reference="center_hubcap">
    <material value="Gazebo/Grey"/>
  </gazebo>
  <gazebo>
    <plugin filename="libgazebo_ros_diff_drive.so" name="differential_drive_controller">
      <rosDebugLevel>Debug</rosDebugLevel>
      <robotNamespace/>
      <publishWheelTF>false</publishWheelTF>
      <publishWheelJointState>true</publishWheelJointState>
      <alwaysOn>true</alwaysOn>
      <leftJoint>left_hub_joint</leftJoint>
      <rightJoint>right_hub_joint</rightJoint>
      <wheelSeparation>0.3</wheelSeparation>
      <wheelDiameter>0.18</wheelDiameter>
      <wheelTorque>20</wheelTorque>
      <wheelAcceleration>1.8</wheelAcceleration>
      <commandTopic>cmd_vel</commandTopic>
      <odometryTopic>odom</odometryTopic>
      <odometryFrame>odom</odometryFrame>
      <odometrySource>world</odometrySource>
      <robotBaseFrame>p3dx_base_link</robotBaseFrame>
      <updateRate>10.0</updateRate>
    </plugin>
  </gazebo>
  <gazebo>
    <plugin filename="libgazebo_ros_joint_state_publisher.so" name="joint_state_publisher">
      <robotNamespace/>
      <jointName>chassis_swivel_joint, swivel_wheel_joint, left_hub_joint, right_hub_joint</jointName>
      <updateRate>10.0</updateRate>
      <alwaysOn>true</alwaysOn>
    </plugin>
  </gazebo>
  <!--  base  -->
  <link name="base_footprint">
    <visual>
      <origin rpy="0 0 0" xyz="0 0 0"/>
      <geometry>
        <sphere radius="0.001"/>
      </geometry>
      <material name="white">
        <color rgba="1 1 1 1"/>
      </material>
    </visual>
  </link>
  <joint name="base_joint" type="fixed">
    <parent link="base_footprint"/>
    <child link="base_link"/>
    <origin rpy="0 0 0" xyz="0.0 0.0 0.0"/>
  </joint>
  <link name="base_link">
    <visual>
      <origin rpy="0 0 0" xyz="0 0 0"/>
      <geometry>
        <mesh filename="package://cyton_gamma_1500_description/meshes/base.dae"/>
      </geometry>
    </visual>
    <inertial>
      <mass value=".0100"/>
      <origin rpy="0 0 0" xyz="0 0 0"/>
      <inertia ixx=".000011027" ixy="0" ixz="0" iyy=".000011027" iyz="0" izz=".000011027"/>
    </inertial>
    <collision>
      <origin xyz="0 0.0115 0.047"/>
      <geometry>
        <box size="0.154 0.177 0.094"/>
      </geometry>
    </collision>
  </link>
  <!-- shoulder roll -->
  <joint name="shoulder_roll_joint" type="revolute">
    <parent link="base_link"/>
    <child link="shoulder_roll"/>
    <origin rpy="0 0 0" xyz="0 0 0.05315"/>
    <limit effort="100.0" lower="-2.618" upper="2.618" velocity="1.0"/>
    <axis xyz="0 0 1"/>
  </joint>
  <link name="shoulder_roll">
    <visual>
      <origin rpy="1.5708 0 0.384" xyz="0 0 0"/>
      <geometry>
        <mesh filename="package://cyton_gamma_1500_description/meshes/shoulder_roll.dae"/>
      </geometry>
    </visual>
    <collision>
      <origin xyz="0.0 0.0 0.05"/>
      <geometry>
        <box size="0.09829 0.046 0.08392"/>
      </geometry>
    </collision>
    <inertial>
      <mass value=".0050"/>
      <origin rpy="0 0 0" xyz="0 0 0"/>
      <inertia ixx=".000001027" ixy="0" ixz="0" iyy=".000001027" iyz="0" izz=".000001027"/>
    </inertial>
  </link>
  <transmission name="tran1">
    <type>transmission_interface/SimpleTransmission</type>
    <joint name="shoulder_roll_joint">
      <hardwareInterface>PositionJointInterface</hardwareInterface>
    </joint>
    <actuator name="motor1">
      <hardwareInterface>PositionJointInterface</hardwareInterface>
    </actuator>
  </transmission>
  <!-- shoulder pitch  -->
  <joint name="shoulder_pitch_joint" type="revolute">
    <parent link="shoulder_roll"/>
    <child link="shoulder_pitch"/>
    <origin rpy="0 0 0" xyz="0.0205 0 0.12435"/>
    <limit effort="100.0" lower="-1.8326" upper="1.8326" velocity="1.0"/>
    <axis xyz="1 0 0"/>
  </joint>
  <link name="shoulder_pitch">
    <visual>
      <origin rpy="1.5708 0 0" xyz="0 0 0"/>
      <geometry>
        <mesh filename="package://cyton_gamma_1500_description/meshes/shoulder_pitch.dae"/>
      </geometry>
    </visual>
    <collision>
      <origin xyz="-0.02 0.0 0.0"/>
      <geometry>
        <sphere radius="0.055"/>
        <!--box size="0.098 0.08 0.11"/-->
      </geometry>
    </collision>
    <inertial>
      <mass value=".0020"/>
      <origin rpy="0 0 0" xyz="0 0 0"/>
      <inertia ixx=".000000827" ixy="0" ixz="0" iyy=".000000827" iyz="0" izz=".000000827"/>
    </inertial>
  </link>
  <transmission name="tran2">
    <type>transmission_interface/SimpleTransmission</type>
    <joint name="shoulder_pitch_joint">
      <hardwareInterface>PositionJointInterface</hardwareInterface>
    </joint>
    <actuator name="motor2">
      <hardwareInterface>PositionJointInterface</hardwareInterface>
    </actuator>
  </transmission>
  <!--  shoulder yaw  -->
  <joint name="shoulder_yaw_joint" type="revolute">
    <parent link="shoulder_pitch"/>
    <child link="shoulder_yaw"/>
    <origin rpy="0 0 0" xyz="-0.0215 -0.0205 0.1255"/>
    <limit effort="100.0" lower="-1.8326" upper="1.8326" velocity="1.0"/>
    <axis xyz="0 -1 0"/>
  </joint>
  <link name="shoulder_yaw">
    <visual>
      <origin rpy="1.5708 0 -1.5708" xyz="0 0 0.0"/>
      <geometry>
        <mesh filename="package://cyton_gamma_1500_description/meshes/shoulder_yaw.dae"/>
      </geometry>
    </visual>
    <collision>
      <origin xyz=" -0.002 0.02 -0.01"/>
      <geometry>
        <sphere radius="0.055"/>
        <!--box size="0.08 0.1 0.11"/-->
      </geometry>
    </collision>
    <inertial>
      <mass value=".0010"/>
      <origin rpy="0 0 0" xyz="0 0 0"/>
      <inertia ixx=".000000627" ixy="0" ixz="0" iyy=".000000627" iyz="0" izz=".000000627"/>
    </inertial>
  </link>
  <transmission name="tran3">
    <type>transmission_interface/SimpleTransmission</type>
    <joint name="shoulder_yaw_joint">
      <hardwareInterface>PositionJointInterface</hardwareInterface>
    </joint>
    <actuator name="motor3">
      <hardwareInterface>PositionJointInterface</hardwareInterface>
    </actuator>
  </transmission>
  <!--  elbow pitch  -->
  <joint name="elbow_pitch_joint" type="revolute">
    <parent link="shoulder_yaw"/>
    <child link="elbow_pitch"/>
    <origin rpy="0 0 0" xyz="0.018 0.0206 0.1158"/>
    <limit effort="100.0" lower="-1.8326" upper="1.8326" velocity="1.0"/>
    <axis xyz="1 0 0"/>
  </joint>
  <link name="elbow_pitch">
    <visual>
      <origin rpy="1.5708 0 3.1416" xyz="0 0 0"/>
      <geometry>
        <mesh filename="package://cyton_gamma_1500_description/meshes/elbow_pitch.dae"/>
      </geometry>
    </visual>
    <collision>
      <origin xyz="-0.022 0.0 -0.006"/>
      <geometry>
        <sphere radius="0.055"/>
        <!--box size="0.09 0.1 0.11"/-->
      </geometry>
    </collision>
    <inertial>
      <mass value=".0010"/>
      <origin rpy="0 0 0" xyz="0 0 0"/>
      <inertia ixx=".000000327" ixy="0" ixz="0" iyy=".000000327" iyz="0" izz=".000000327"/>
    </inertial>
  </link>
  <transmission name="tran4">
    <type>transmission_interface/SimpleTransmission</type>
    <joint name="elbow_pitch_joint">
      <hardwareInterface>PositionJointInterface</hardwareInterface>
    </joint>
    <actuator name="motor4">
      <hardwareInterface>PositionJointInterface</hardwareInterface>
    </actuator>
  </transmission>
  <!--  elbow yaw  -->
  <joint name="elbow_yaw_joint" type="revolute">
    <parent link="elbow_pitch"/>
    <child link="elbow_yaw"/>
    <origin rpy="0 0 0" xyz="-0.0171 -0.018 0.09746"/>
    <limit effort="100.0" lower="-1.8326" upper="1.8326" velocity="1.0"/>
    <axis xyz="0 -1 0"/>
  </joint>
  <link name="elbow_yaw">
    <visual>
      <origin rpy="1.5708 0 1.5708" xyz="0 0 0"/>
      <geometry>
        <mesh filename="package://cyton_gamma_1500_description/meshes/elbow_yaw.dae"/>
      </geometry>
    </visual>
    <collision>
      <origin xyz="0.0 0.025 0.0"/>
      <geometry>
        <sphere radius="0.05"/>
      </geometry>
    </collision>
    <inertial>
      <mass value=".0010"/>
      <origin rpy="0 0 0" xyz="0 0 0"/>
      <inertia ixx=".000000227" ixy="0" ixz="0" iyy=".000000227" iyz="0" izz=".000000227"/>
    </inertial>
  </link>
  <transmission name="tran5">
    <type>transmission_interface/SimpleTransmission</type>
    <joint name="elbow_yaw_joint">
      <hardwareInterface>PositionJointInterface</hardwareInterface>
    </joint>
    <actuator name="motor5">
      <hardwareInterface>PositionJointInterface</hardwareInterface>
    </actuator>
  </transmission>
  <!--  wrist pitch  -->
  <joint name="wrist_pitch_joint" type="revolute">
    <parent link="elbow_yaw"/>
    <child link="wrist_pitch"/>
    <origin rpy="0 0 0" xyz="0.02626 0.018 0.0718"/>
    <limit effort="100.0" lower="-1.8326" upper="1.8326" velocity="1.0"/>
    <axis xyz="1 0 0"/>
  </joint>
  <link name="wrist_pitch">
    <visual>
      <origin rpy="1.5708 0 1.5708" xyz="0 0 0"/>
      <geometry>
        <mesh filename="package://cyton_gamma_1500_description/meshes/wrist_pitch.dae"/>
      </geometry>
    </visual>
    <collision>
      <origin xyz="-0.02 0.0 0.0"/>
      <geometry>
        <box size="0.07 0.06 0.11"/>
      </geometry>
    </collision>
    <inertial>
      <mass value=".0010"/>
      <origin rpy="0 0 0" xyz="0 0 0"/>
      <inertia ixx=".000000127" ixy="0" ixz="0" iyy=".000000127" iyz="0" izz=".000000127"/>
    </inertial>
  </link>
  <transmission name="tran6">
    <type>transmission_interface/SimpleTransmission</type>
    <joint name="wrist_pitch_joint">
      <hardwareInterface>PositionJointInterface</hardwareInterface>
    </joint>
    <actuator name="motor6">
      <hardwareInterface>PositionJointInterface</hardwareInterface>
    </actuator>
  </transmission>
  <!--  wrist roll  -->
  <joint name="wrist_roll_joint" type="revolute">
    <parent link="wrist_pitch"/>
    <child link="wrist_roll"/>
    <origin rpy="0 0 0" xyz="-0.026255 0 0.051425"/>
    <limit effort="100.0" lower="-2.61799" upper="2.61799" velocity="1.0"/>
    <axis xyz="0 0 1"/>
  </joint>
  <link name="wrist_roll">
    <visual>
      <origin rpy="3.1416 0 -1.5708" xyz="0 0 0"/>
      <geometry>
        <mesh filename="package://cyton_gamma_1500_description/meshes/wrist_roll.dae"/>
      </geometry>
    </visual>
    <collision>
      <origin xyz="0.0 0.008 0.04"/>
      <geometry>
        <box size="0.08 0.06 0.08"/>
      </geometry>
    </collision>
    <inertial>
      <mass value=".0010"/>
      <origin rpy="0 0 0" xyz="0 0 0"/>
      <inertia ixx=".000000027" ixy="0" ixz="0" iyy=".000000027" iyz="0" izz=".000000027"/>
    </inertial>
  </link>
  <transmission name="tran7">
    <type>transmission_interface/SimpleTransmission</type>
    <joint name="wrist_roll_joint">
      <hardwareInterface>PositionJointInterface</hardwareInterface>
    </joint>
    <actuator name="motor7">
      <hardwareInterface>PositionJointInterface</hardwareInterface>
    </actuator>
  </transmission>
  <gazebo>
    <plugin filename="libgazebo_ros_control.so" name="gazebo_ros_control"/>
  </gazebo>
  <gazebo>
    <plugin filename="libgazebo_ros_joint_state_publisher.so" name="joint_state_publisher">
      <jointName>shoulder_roll_joint, shoulder_pitch_joint, shoulder_yaw_joint, elbow_pitch_joint, elbow_yaw_joint, wrist_pitch_joint, wrist_roll_joint</jointName>
    </plugin>
  </gazebo>
  <!--  virtual gripper  stuff  -->
  <joint name="virtual_endeffector_joint" type="fixed">
    <parent link="wrist_roll"/>
    <child link="virtual_endeffector"/>
    <origin rpy="0 0 0" xyz="-0.002316 0.0079 0.099425"/>
  </joint>
  <link name="virtual_endeffector">
    <visual>
      <!-- places the point to plan for in middle of wrist roll -->
      <!-- xyz should be offest by gripper size if center -->
      <!-- of gripper is desired -->
      <origin rpy="0 0 0" xyz="0 0 0"/>
      <geometry>
        <sphere radius="0.002"/>
      </geometry>
      <material name="grey">
        <color rgba="0.7 0.7 0.7 0.8"/>
      </material>
    </visual>
  </link>
  <joint name="p3dx_joint" type="fixed">
    <parent link="chassis"/>
    <child link="base_footprint"/>
    <origin rpy="0 0 1.57079633" xyz="0 0 .235"/>
  </joint>
  <!--  gripper  stuff  -->
  <!--xacro:include filename="$(find p3dx_cyton1500_fusion)/xacro/cyton1500_gripper.xacro"/-->
  <joint name="base_camera_joint" type="fixed">
    <origin rpy="0 0 0" xyz="0.21 0.009 0.05 "/>
    <parent link="top"/>
    <origin rpy="0 0 0" xyz="0 0 0"/>
    <child link="camera_link"/>
  </joint>
  <link name="camera_link">
    <inertial>
      <mass value="0.01"/>
      <origin xyz="0 0 0"/>
      <inertia ixx="0.001" ixy="0.0" ixz="0.0" iyy="0.001" iyz="0.0" izz="0.001"/>
    </inertial>
    <visual>
      <origin rpy="0 0 0" xyz=" 0 0 0 "/>
      <geometry>
        <mesh filename="package://kinect_description/meshes/kinect.dae"/>
      </geometry>
    </visual>
    <collision>
      <origin rpy="0 0 0" xyz="0.0 0.0 0.0"/>
      <geometry>
        <box size="0.0730 .2760 0.0720"/>
      </geometry>
    </collision>
  </link>
  <joint name="camera_depth_joint" type="fixed">
    <origin rpy="0 0 0" xyz="0 0.011 0"/>
    <parent link="camera_link"/>
    <child link="camera_depth_frame"/>
  </joint>
  <link name="camera_depth_frame">
    <inertial>
      <mass value="0.01"/>
      <origin xyz="0 0 0"/>
      <inertia ixx="0.001" ixy="0.0" ixz="0.0" iyy="0.001" iyz="0.0" izz="0.001"/>
    </inertial>
  </link>
  <joint name="camera_depth_optical_joint" type="fixed">
    <origin rpy="-1.57079632679 0 -1.57079632679" xyz="0 0 0"/>
    <parent link="camera_depth_frame"/>
    <child link="camera_depth_optical_frame"/>
  </joint>
  <link name="camera_depth_optical_frame">
    <inertial>
      <mass value="0.001"/>
      <origin xyz="0 0 0"/>
      <inertia ixx="0.0001" ixy="0.0" ixz="0.0" iyy="0.0001" iyz="0.0" izz="0.0001"/>
    </inertial>
  </link>
  <joint name="camera_rgb_joint" type="fixed">
    <origin rpy="0 0 0" xyz="0 -0.012 0"/>
    <parent link="camera_link"/>
    <child link="camera_rgb_frame"/>
  </joint>
  <link name="camera_rgb_frame">
    <inertial>
      <mass value="0.001"/>
      <origin xyz="0 0 0"/>
      <inertia ixx="0.0001" ixy="0.0" ixz="0.0" iyy="0.0001" iyz="0.0" izz="0.0001"/>
    </inertial>
  </link>
  <joint name="camera_rgb_optical_joint" type="fixed">
    <origin rpy="-1.57079632679 0 -1.57079632679" xyz="0 0 0"/>
    <parent link="camera_rgb_frame"/>
    <child link="camera_rgb_optical_frame"/>
  </joint>
  <link name="camera_rgb_optical_frame">
    <inertial>
      <mass value="0.001"/>
      <origin xyz="0 0 0"/>
      <inertia ixx="0.0001" ixy="0.0" ixz="0.0" iyy="0.0001" iyz="0.0" izz="0.0001"/>
    </inertial>
  </link>
  <gazebo reference="camera_link">
    <sensor name="kinect" type="depth">
      <always_on>true</always_on>
      <update_rate>30.0</update_rate>
      <camera>
        <horizontal_fov>1.0471975512</horizontal_fov>
        <image>
          <format>B8G8R8</format>
          <width>640</width>
          <height>480</height>
        </image>
        <clip>
          <near>0.05</near>
          <far>8.0</far>
        </clip>
      </camera>
      <plugin filename="libgazebo_ros_openni_kinect.so" name="kinect_camera_controller">
        <cameraName>kinect</cameraName>
        <alwaysOn>true</alwaysOn>
        <updateRate>10</updateRate>
        <imageTopicName>rgb/image_raw</imageTopicName>
        <depthImageTopicName>depth/image_raw</depthImageTopicName>
        <pointCloudTopicName>depth/points</pointCloudTopicName>
        <cameraInfoTopicName>rgb/camera_info</cameraInfoTopicName>
        <depthImageCameraInfoTopicName>depth/camera_info</depthImageCameraInfoTopicName>
        <frameName>be/camera_link</frameName>
        <baseline>0.1</baseline>
        <distortion_k1>0.0</distortion_k1>
        <distortion_k2>0.0</distortion_k2>
        <distortion_k3>0.0</distortion_k3>
        <distortion_t1>0.0</distortion_t1>
        <distortion_t2>0.0</distortion_t2>
        <pointCloudCutoff>0.4</pointCloudCutoff>
      </plugin>
    </sensor>
  </gazebo>
  <!-- Not a complete solution for getting gripper and lazer working together 
		<disable_collisions link1="QS18VP6LLP_laser_link" link2="gripper_finger1" reason="Adjacent" />
		<disable_collisions link1="QS18VP6LLP_laser_link" link2="gripper_finger2" reason="Adjacent" />
		<disable_collisions link1="QS18VP6LLP_laser_link" link2="wrist_roll" reason="Adjacent" />
		<disable_collisions link1="gripper_finger1" link2="wrist_roll" reason="Adjacent" />
		<disable_collisions link1="gripper_finger2" link2="wrist_roll" reason="Adjacent" />
	-->
</robot>
